<mujoco model="Arm">
	<option gravity="0 0 -9.81" timestep="0.01"/>


    <asset>
        <!-- Texture for the floor -->
        <texture name="texplane" type="2d" builtin="checker" rgb1="0.8 0.8 0.8" rgb2="0.2 0.2 0.2" width="512" height="512" mark="cross" markrgb="1 0 0"/>
        <material name="matplane" texture="texplane" texrepeat="4 4" texuniform="true"/>
    </asset>

    <worldbody>
        <!-- Floor Geometry -->
        <geom name="floor" type="plane" size="10 10 0.1" pos="0 0 0" material="matplane" rgba="0.8 0.8 0.8 1"/>
        <site name = "site0" pos="0 0 1.15" size="0.02" type="sphere" rgba="0 0 255 1" />
        <site name="x0" pos="-0.15 0 1" size="0.02" rgba="0 .7 0 1" group="1"/>

    <body name="shoulder" pos="0 0 1">
	    <site name="site1" type="sphere" pos="-0.09 0 -.13" size="0.02" rgba="0 255 255 1"/>
        <site name="x1" pos="-0.15 0 -.15" size="0.02" rgba="0 .7 0 1" group="1"/>
        <joint name="shoulder_joint" type="ball" />
        <geom name="geom_shoulder" type="sphere" size="0.07" rgba="0 0 255 1" />
<!-- Upper Arm (Red Rod) Extending Downward -->
            <body name="upper_arm" pos="0 0 0">

            <!-- Upper Arm Geometry -->
            <geom name="geom_upperarm" type="capsule" size="0.05 0.2" fromto="0 0 0 0 0 -0.27" rgba="255 0 0 1" />


                <body name="elbow" pos="0 0 -0.27">


                <!-- Elbow Sphere Geometry (Blue) -->
                <geom name="geom_elbow" type="sphere" size="0.06" rgba="0 0 255 1" />
                <site name="site2" pos="-0.06 0 -.05" size="0.02"/>
                <!-- Elbow Hinge Joint -->
                <joint name="elbow_joint" type="hinge" axis="0 1 0" range="0 135" />


                    <!-- Forearm (Green Rod) Extending from Elbow -->
                    <body name="forearm" pos="0 0 0">



                    <!-- Forearm Geometry -->
                    <geom name="geom_forearm" type="capsule" size="0.05 0.2" fromto="0 0 0 0 0 -0.2" rgba="0 255 0 1" />


                    </body>
                </body>
            </body>
	</body>
</worldbody>

<tendon>


    <spatial name="bicep" width="0.009" rgba=".4 .6 .4 1">
      <site site="site0"/>
      <geom geom="geom_shoulder" sidesite="x0"/>
      <site site="site1"/>
      <geom geom="geom_elbow" sidesite="x1"/>
      <site site="site2"/>
    </spatial>
  </tendon>




      <actuator>
        <muscle name="bicep" tendon="bicep" lengthrange="0 5" ctrlrange="0 1"/>
    </actuator>
</mujoco>





