<mujoco>
    <option gravity="0 0 -9.81" timestep="0.01"/>
    <!-- World body definition -->

    <asset>
        <texture name="texplane" type="2d" builtin="checker" rgb1="0.8 0.8 0.8" rgb2="0.2 0.2 0.2" width="512" height="512" mark="cross" markrgb="1 0 0"/>
        <material name="matplane" texture="texplane" texrepeat="4 4" texuniform="true"/>
    </asset>


    <worldbody>
        <geom name="floor" type="plane" size="10 10 0.1" pos="0 0 0" material="matplane" rgba="0.8 0.8 0.8 1"/>
        <!-- Base body -->
        <!-- Torso -->
        <body name="torso" pos="0 0 1.5">
            <!-- Top Section -->
            <geom name="torso_top" type="ellipsoid" size="0.18 0.12 0.10" pos="0 0 0.12" rgba="0.7 0.7 0.7 1"/>
            <!-- Middle Section (Slimmer) -->
            <geom name="torso_middle" type="ellipsoid" size="0.15 0.10 0.08" pos="0 0 0" rgba="0.7 0.7 0.7 1"/>
            <!-- Bottom Section -->
            <geom name="torso_bottom" type="ellipsoid" size="0.16 0.12 0.10" pos="0 0 -0.12" rgba="0.7 0.7 0.7 1"/>
            <joint name="torso_joint" type="hinge" axis="0 1 0" range="-25 25"/>
            


             <!-- Left Sites -->

            <site name="top_site" pos="-0.07 0 -0.1" size="0.02" rgba="0 0 1 1"/>
            <site name="x0" pos="-0.07 -0.1 -0.2" size="0.02" rgba="0 0 1 1"/>
            <site name="x0_back" pos="-0.07 0.1 -0.2" size="0.02" rgba="0 0 1 1"/>
            <site name="x0_side" pos="-0.15 0 -0.2" size="0.02" rgba="0 0 1 1"/>

             
             <!--Right Sites -->
            <site name="top_site2" pos="0.07 0 -0.1" size="0.02" rgba="0 0 1 1"/>
            <site name="x0_2" pos="0.07 -0.1 -0.2" size="0.02" rgba="0 0 1 1"/>
            <site name="x0_back2" pos="0.07 0.1 -0.2" size="0.02" rgba="0 0 1 1"/>
            <site name="x0_side2" pos="0.15 0 -0.2" size="0.02" rgba="0 0 1 1"/>


            <!-- Pelvis -->
            <body name="pelvis" pos="0 0 -0.24">
                <!-- Pelvis geometry -->
                <!-- <geom name="pelvis_geom" type="ellipsoid" size="0.2 0.07 0.09" rgba="0 0 255 1"/> -->
            
               <!-- <joint name="pelvis_joint" type="hinge" axis="0 0 1" range="-25 25"/> -->

                <!-- Hip -->
                <body name="hip" pos="-0.07 0 -0.06">
                    <!-- Hip site -->
                    <site name="site1" pos="0 0 0.1" size="0.02" rgba="0 0 1 1"/>
                    <!-- <site name="side_site" pos="0 -0.05 0.25" size="0.02" rgba="0 0 1 1"/> -->
                    
                    <!-- Hip geometry -->
                    <geom name="hip_geom" type="sphere" size="0.07" rgba="0 0 255 1" group="1"/>
                    <joint name="hip_joint" type="hinge" axis="1 0 0" range="-90 30" />
                    <joint name="hip_joint_side" type="hinge" axis="0 1 0" range="-30 30" />

                    <!-- Upper leg -->
                    <body name="upper_leg" pos="0 0 0">
                        <!-- Upper leg geometry -->
                        <geom name="upper_leg_geom" type="capsule" size="0.045 0.2" fromto="0 0 0 0 0 -0.27" rgba="255 0 0 1"/>
                        <!-- Hamstring and quadriceps sites -->
                        <site name="ham_site2" pos="0 0.08 -0.08" size="0.02" rgba="0 1 0 1"/>
                        
                        <site name="quad_site2" pos="0 -0.08 -0.2" size="0.02" rgba="0 1 0 1"/>
                        <site name="upper_leg_top_site" pos="0 -0.1 -0.1" size="0.02" rgba="0 0 1 1"/>
                        <site name="upper_leg_top_site_back" pos="0 0.1 -0.1" size="0.02" rgba="0 0 1 1"/>
                        <site name="upper_leg_top_site_side" pos="-0.1 0 -0.1" size="0.02" rgba="0 0 1 1"/>
                        
                        <site name="upper_leg" pos="0 -0.06 -0.2" size="0.02" rgba="0 1 0 1"/>
                        <site name="upper_leg_back" pos="0 0.06 -0.2" size="0.02" rgba="0 1 0 1"/>
                        <site name="upper_leg_side" pos="-0.06 0 -0.2" size="0.02" rgba="0 1 0 1"/>
                        

                        <!-- Knee -->
                        <body name="knee" pos="0 0 -0.27">
                            <!-- Knee joint -->
                            <joint name="knee_joint" type="hinge" axis="1 0 0" range="-5 120"/>
                            <!-- Knee geometry -->
                            <geom name="knee_geom" type="sphere" size="0.06" rgba="0 0 255 1" group="1"/>
                            <!-- Additional sites for tendons -->
                            <site name="ham_site3" pos="0 0.06 -0.10" size="0.02" rgba="1 0 1 1"/>
                            <site name="quad_site3" pos="0 -0.06 -0.10" size="0.02" rgba="1 0 1 1"/>
                            
                            <site name="x2" pos="0 -0.2 0" size="0.02" rgba="0 1 0 1"/>

                            <!-- Lower leg -->
                            <body name="lower_leg" pos="0 0 0">
                                <!-- Lower leg geometry -->
                                <geom name="lower_leg" type="capsule" size="0.04 0.2" fromto="0 0 0 0 0 -0.3" rgba="0 255 0 1"/>
                                <site name="calf_front_site_left" pos="0 -0.06 -0.25" size="0.02" rgba="1 0 1 1"/>
                                <site name="calf_back_site_left" pos="0 0.06 -0.25" size="0.02" rgba="1 0 1 1"/>

                                <!-- Ankle -->
                                <body name="ankle" pos="0 0 -0.3">
                                    <!-- Ankle joint -->
                                    <joint name="ankle_joint" type="hinge" axis="1 0 0" range="-10 75"/>
                                    <!-- Ankle geometry -->
                                    <geom name="ankle_geom" type="sphere" size="0.05" rgba="255 43 54 1" group="1"/>
                                    <site name="achilles_front_site_left"  size="0.02" pos="0 -0.08 -0.01" rgba="1 0 0 1"/>
                                    <site name="achilles_back_site_left"  size="0.02" pos="0 0.01 -0.01" rgba="1 0 0 1"/>


                                    <!-- Foot -->
                                    <body name="foot" pos="0 -0.05 -0.05">
                                        <!-- Foot geometry -->
                                        <geom name="foot_geom" type="box" size="0.06 0.12 0.02" rgba="255 0 0 1"/>
                                    </body>
                                </body>
                            </body>
                        </body>
                    </body>
                </body>


                <!-- Hip -->
                <body name="hip_right" pos="0.07 0 -0.06">
                    <!-- Hip site -->
                    <site name="site1_right" pos="0 0 0.1" size="0.02" rgba="0 0 1 1"/>
                    <!-- Hip geometry -->
                    <geom name="hip_geom_right" type="sphere" size="0.07" rgba="0 0 255 1" group="1"/>
                    <joint name="hip_joint_right" type="hinge" axis="1 0 0" range="-90 30" />
                    <joint name="hip_joint_side_right" type="hinge" axis="0 1 0" range="-30 30" />

                    <!-- Upper leg -->
                    <body name="upper_leg_right" pos="0 0 0">
                        <!-- Upper leg geometry -->
                        <geom name="geom_upperleg_right" type="capsule" size="0.045 0.2" fromto="0 0 0 0 0 -0.27" rgba="255 0 0 1"/>
                        <!-- Hamstring and quadriceps sites -->
                        <site name="ham_site2_right" pos="0 0.08 -0.08" size="0.02" rgba="0 1 0 1"/>
                        <site name="quad_site2_right" pos="0 -0.08 -0.2" size="0.02" rgba="0 1 0 1"/>
                        <site name="upper_leg_top_site2" pos="0 -0.1 -0.1" size="0.02" rgba="0 0 1 1"/>
                        <site name="upper_leg_top_site_back2" pos="0 0.1 -0.1" size="0.02" rgba="0 0 1 1"/>
                        <site name="upper_leg_top_site_side2" pos="0.1 0 -0.1" size="0.02" rgba="0 0 1 1"/>

                        <site name="upper_leg_right" pos="0 -0.06 -0.2" size="0.02" rgba="0 1 0 1"/>
                        <site name="upper_leg_back2" pos="0 0.06 -0.2" size="0.02" rgba="0 1 0 1"/>
                        <site name="upper_leg_side2" pos="0.06 0 -0.2" size="0.02" rgba="0 1 0 1"/>




                        <!-- Knee -->
                        <body name="knee_right" pos="0 0 -0.27">
                            <!-- Knee joint -->
                            <joint name="knee_joint_right" type="hinge" axis="1 0 0" range="-5 120"/>
                            <!-- Knee geometry -->
                            <geom name="knee_geom_right" type="sphere" size="0.06" rgba="0 0 255 1" group="1"/>
                            <!-- Additional sites for tendons -->
                            <site name="ham_site3_right" pos="0 0.06 -0.10" size="0.02" rgba="1 0 1 1"/>
                            <site name="quad_site3_right" pos="0 -0.06 -0.10" size="0.02" rgba="1 0 1 1"/>
                            <site name="x2_right" pos="0 -0.2 0" size="0.02" rgba="0 1 0 1"/>


                            <!-- Lower leg -->
                            <body name="lower_leg_right" pos="0 0 0">
                                <!-- Lower leg geometry -->
                                <geom name="lower_leg_right" type="capsule" size="0.04 0.2" fromto="0 0 0 0 0 -0.3" rgba="0 255 0 1"/>
                                <site name="calf_front_site_right" pos="0 -0.06 -0.25" size="0.02" rgba="1 0 1 1"/>
                                <site name="calf_back_site_right" pos="0 0.06 -0.25" size="0.02" rgba="1 0 1 1"/>

                                <!-- Ankle -->
                                <body name="ankle_right_right" pos="0 0 -0.3">
                                    <!-- Ankle joint -->
                                    <joint name="ankle_right_joint" type="hinge" axis="1 0 0" range="-10 75"/>
                                    <!-- Ankle geometry -->
                                    <geom name="ankle_right_geom" type="sphere" size="0.05" rgba="255 43 54 1" group="1"/>
                                    <site name="achilles_front_site_right"  size="0.02" pos="0 -0.08 -0.01" rgba="1 0 0 1"/>
                                    <site name="achilles_back_site_right"  size="0.02" pos="0 0.01 -0.01" rgba="1 0 0 1"/>

                                    <!-- Foot -->
                                    <body name="foot_right" pos="0 -0.05 -0.05">
                                        <!-- Foot geometry -->
                                        <geom name="foot_right_geom" type="box" size="0.06 0.12 0.02" rgba="255 0 0 1"/>
                                    </body>
                                </body>
                            </body>
                        </body>
                    </body>
                </body>
            </body>
        </body>
</worldbody>


<!-- Tendons -->
    <tendon>
       
       <spatial name="upper_leg" width="0.009" rgba=".4 .6 .4 1" group="2">
            
            <site site="top_site"/>
            <geom geom="hip_geom" sidesite="x0"/>
            <site site="upper_leg_top_site"/>
            
            <site site="upper_leg"/>

        </spatial>

               <spatial name="upper_leg_side" width="0.009" rgba=".4 .6 .4 1" group="2">
            
            <site site="top_site"/>
            <geom geom="hip_geom" sidesite="x0_side"/>
            <site site="upper_leg_top_site_side"/>
            
            <site site="upper_leg_side"/>

      
        </spatial>

         <spatial name="upper_leg_back" width="0.009" rgba=".4 .6 .4 1" group="2">
            
            <site site="top_site"/>
            <geom geom="hip_geom" sidesite="x0_back"/>
            <site site="upper_leg_top_site_back"/>
            
            <site site="upper_leg_back"/>

      
        </spatial>

      
        <spatial name="upper_leg_right" width="0.009" rgba=".4 .6 .4 1" group="2">
            <site site="top_site2"/> <!-- Corresponding site for the right leg -->
            <geom geom="hip_geom_right" sidesite="x0_2"/> <!-- Corresponding hip geometry for the right leg -->
            <site site="upper_leg_top_site2"/>
            <site site="upper_leg_right"/>

        </spatial>

                <spatial name="upper_leg_side_right" width="0.009" rgba=".4 .6 .4 1" group="2">

            <site site="top_site2"/>
            <geom geom="hip_geom_right" sidesite="x0_side2"/>
            <site site="upper_leg_top_site_side2"/>
            <site site="upper_leg_side2"/>
        </spatial>

        <spatial name="upper_leg_back_right" width="0.009" rgba=".4 .6 .4 1" group="2">
            <site site="top_site2"/>
            <geom geom="hip_geom_right" sidesite="x0_back2"/>
            <site site="upper_leg_top_site_back2"/>
            <site site="upper_leg_back2"/>

        </spatial>






        <!-- Hamstring tendon -->
        <spatial name="hamstring" width="0.009" rgba=".4 .6 .4 1" group="1">
            <site site="site1"/>
            <geom geom="hip_geom"/>
            <site site="ham_site2"/>
            <geom geom="knee_geom"/>
            <site site="ham_site3"/>
        </spatial>

        <!-- Quadriceps tendon -->
        <spatial name="quad" width="0.009" rgba=".4 .6 .4 1" group="1">
            <site site="site1"/>
            <geom geom="hip_geom"/>
            <site site="quad_site2"/>
            <geom geom="knee_geom" sidesite="x2"/>
            <site site="quad_site3"/>
        </spatial>




        <!-- Hamstring tendon -->
        <spatial name="hamstring_right" width="0.009" rgba=".4 .6 .4 1" group="1">
            <site site="site1_right"/>
            <geom geom="hip_geom_right"/>
            <site site="ham_site2_right"/>
            <geom geom="knee_geom_right"/>
            <site site="ham_site3_right"/>
        </spatial>

        <!-- Quadriceps tendon -->
        <spatial name="quad_right" width="0.009" rgba=".4 .6 .4 1" group="1">
            <site site="site1_right"/>
            <geom geom="hip_geom_right"/>
            <site site="quad_site2_right"/>
            <geom geom="knee_geom_right" sidesite="x2_right"/>
            <site site="quad_site3_right"/>
        </spatial>


        <spatial name="calf_front_tendon_right" width="0.009" rgba=".4 .6 .4 1" group="1">
            <site site="quad_site3_right"/>
            <site site="calf_front_site_right"/>
            <site site="achilles_front_site_right"/>
        </spatial>

        <spatial name="calf_back_tendon_right" width="0.009" rgba=".4 .6 .4 1" group="1">
            <site site="ham_site3_right"/>
            <site site="calf_back_site_right"/>
            <site site="achilles_back_site_right"/>
        </spatial>

        <spatial name="calf_front_tendon_left" width="0.009" rgba=".4 .6 .4 1" group="1">
            <site site="quad_site3"/>
            <site site="calf_front_site_left"/>
            <site site="achilles_front_site_left"/>
        </spatial>

        <spatial name="calf_back_tendon_left" width="0.009" rgba=".4 .6 .4 1" group="1">
            <site site="ham_site3"/>
            <site site="calf_back_site_left"/>
            <site site="achilles_back_site_left"/>
        </spatial>





    </tendon>



    <!-- Actuators -->
    <actuator>


        <!-- Upperleg muscle -->
        <muscle name="upper_leg" tendon="upper_leg" lengthrange="0 1" ctrlrange="0 1" group="1"/>

        <muscle name="upper_leg_side" tendon="upper_leg_side" lengthrange="0 1" ctrlrange="0 .2" group="1"/>

        <muscle name="upper_leg_back" tendon="upper_leg_back" lengthrange="0 1" ctrlrange="0 1" group="1"/>


        <muscle name="upper_leg_right" tendon="upper_leg_right" lengthrange="0 1" ctrlrange="0 1" group="1"/>

        <muscle name="upper_leg_side_right" tendon="upper_leg_side_right" lengthrange="0 5" ctrlrange="0 .2" group="1"/>

        <muscle name="upper_leg_back_right" tendon="upper_leg_back_right" lengthrange="0 1" ctrlrange="0 1" group="1"/>


        <muscle name="upper_leg_right" tendon="upper_leg_right" lengthrange="0 5" ctrlrange="0 1" group="1"/>

        <muscle name="upper_leg_side_right" tendon="upper_leg_side_right" lengthrange="0 5" ctrlrange="0 .2" group="1"/>

        <muscle name="upper_leg_back_right" tendon="upper_leg_back_right" lengthrange="0 5" ctrlrange="0 1" group="1"/>



        <!-- Hamstring muscle -->
        <muscle name="hamstring" tendon="hamstring" lengthrange="0 1" ctrlrange="0 1"/>
        <!-- Quadriceps muscle -->
        <muscle name="quad" tendon="quad" lengthrange="0 1" ctrlrange="0 1"/>


        <!-- Hamstring muscle -->
        <muscle name="hamstring_right" tendon="hamstring_right" lengthrange="0 1" ctrlrange="0 1"/>
        <!-- Quadriceps muscle -->
        <muscle name="quad_right" tendon="quad_right" lengthrange="0 1" ctrlrange="0 1"/>

        <muscle name="calf_front_tendon_right" tendon="calf_front_tendon_right" lengthrange="0 1" ctrlrange="0 1"/>

        <muscle name="calf_back_tendon_right" tendon="calf_back_tendon_right" lengthrange="0 1" ctrlrange="0 1"/>



        <muscle name="calf_front_tendon_right2" tendon="calf_front_tendon_right" lengthrange="0 1" ctrlrange="0 1"/>

        <muscle name="calf_back_tendon_right2" tendon="calf_back_tendon_right" lengthrange="4 1" ctrlrange="0 1"/>


        <muscle name="calf_front_tendon_left2" tendon="calf_front_tendon_left" lengthrange="0 1" ctrlrange="0 1"/>

        <muscle name="calf_back_tendon_left2" tendon="calf_back_tendon_left" lengthrange="0 1" ctrlrange="0 1"/>





        <muscle name="calf_front_tendon_left" tendon="calf_front_tendon_left" lengthrange="0 1" ctrlrange="0 1"/>

        <muscle name="calf_back_tendon_left" tendon="calf_back_tendon_left" lengthrange="0 1" ctrlrange="0 1"/>

    </actuator>

</mujoco>
