<mujoco model="full_model">
    <option gravity="0 0 -9.81" timestep="0.01"/>

    <asset>
        <texture name="texplane" type="2d" builtin="checker" rgb1="0.8 0.8 0.8" rgb2="0.2 0.2 0.2" width="512" height="512" mark="cross" markrgb="1 0 0"/>
        <material name="matplane" texture="texplane" texrepeat="4 4" texuniform="true"/>
    </asset>

    <worldbody>
        <!-- Floor -->
        <geom name="floor" type="plane" size="10 10 0.1" pos="0 0 0" material="matplane" rgba="0.8 0.8 0.8 1"/>

        <!-- Torso -->
        <body name="torso" pos="0 0 1.5">
            <geom name="torso_geom" type="box" size="0.15 0.1 0.3" rgba="0.7 0.7 0.7 1"/>
            <joint name="torso_joint" type="free"/>

            <!-- Pelvis -->
            <body name="pelvis" pos="0 0 -0.4">
                <geom name="pelvis_geom" type="ellipsoid" size="0.2 0.07 0.07" rgba="0 0 255 1"/>
                <joint name="pelvis_joint" type="ball"/>

                <!-- Right Leg -->
                <body name="hip_right" pos="0.09 0 -0.04">
                    <joint name="hip_right_joint" type="ball"/>
                    <geom name="hip_right_geom" type="sphere" size="0.05" rgba="0 255 0 1"/>
                    <body name="upper_leg_right" pos="0 0 -0.15">
                        <geom name="upper_leg_right_geom" type="capsule" size="0.05 0.1" rgba="255 255 0 1"/>
                        <body name="knee_right" pos="0 0 -0.135">
                            <joint name="knee_right_joint" type="ball"/>
                            <geom name="knee_right_geom" type="sphere" size="0.06" rgba="0 255 0 1"/>
                            <body name="lower_leg_right" pos="0 0 -0.16">
                                <geom name="lower_leg_right_geom" type="capsule" size="0.05 0.1" rgba="255 0 54 1"/>
                                <body name="ankle_right" pos="0 0 -0.14">
                                    <joint name="ankle_right_joint" type="ball"/>
                                    <geom name="ankle_right_geom" type="sphere" size="0.05" rgba="255 43 54 1"/>
                                    <body name="foot_right" pos="0 0 -0.12">
                                        <geom name="foot_right_geom" type="box" size="0.07 0.15 0.02" rgba="255 0 0 1"/>
                                    </body>
                                </body>
                            </body>
                        </body>
                    </body>
                </body>

                <!-- Left Leg -->
                <body name="hip_left" pos="-0.09 0 -0.04">
                    <joint name="hip_left_joint" type="ball"/>
                    <geom name="hip_left_geom" type="sphere" size="0.05" rgba="0 255 0 1"/>
                    <body name="upper_leg_left" pos="0 0 -0.15">
                        <geom name="upper_leg_left_geom" type="capsule" size="0.05 0.1" rgba="255 255 0 1"/>
                        <body name="knee_left" pos="0 0 -0.135">
                            <joint name="knee_left_joint" type="ball"/>
                            <geom name="knee_left_geom" type="sphere" size="0.06" rgba="0 255 0 1"/>
                            <body name="lower_leg_left" pos="0 0 -0.16">
                                <geom name="lower_leg_left_geom" type="capsule" size="0.05 0.1" rgba="255 0 54 1"/>
                                <body name="ankle_left" pos="0 0 -0.14">
                                    <joint name="ankle_left_joint" type="ball"/>
                                    <geom name="ankle_left_geom" type="sphere" size="0.05" rgba="255 43 54 1"/>
                                    <body name="foot_left" pos="0 0 -0.12">
                                        <geom name="foot_left_geom" type="box" size="0.07 0.15 0.02" rgba="255 0 0 1"/>
                                    </body>
                                </body>
                            </body>
                        </body>
                    </body>
                </body>
            </body>

            <!-- Arm -->
            <body name="shoulder" pos="0.2 0 0.1">
                <site name="site0" pos="0 0 0.15" size="0.02" rgba="0 0 1 1"/>
                <site name="x0" pos="0 0 -0.05" size="0.02" rgba="1 0 0 1"/>
                <joint name="shoulder_joint" type="ball"/>
                <geom name="geom_shoulder" type="sphere" size="0.07" rgba="0 0 255 1"/>

                <body name="upper_arm" pos="0 0 0">
                    <geom name="geom_upperarm" type="capsule" size="0.05 0.2" fromto="0 0 0 0 0 -0.27" rgba="255 0 0 1"/>
                    <site name="site1" pos="0 0 -0.13" size="0.02" rgba="0 1 0 1"/>
                    <body name="elbow" pos="0 0 -0.27">
                        <geom name="geom_elbow" type="sphere" size="0.06" rgba="0 0 255 1"/>
                        <site name="x1" pos="0 0 -0.25" size="0.02" rgba="0 1 1 1"/>
                        <body name="forearm" pos="0 0 0">
                            <geom name="geom_forearm" type="capsule" size="0.05 0.2" fromto="0 0 0 0 0 -0.2" rgba="0 255 0 1"/>
                            <site name="site2" pos="0 0 -0.45" size="0.02" rgba="1 0 1 1"/>
                        </body>
                    </body>
                </body>
            </body>
        </body>
    </worldbody>

    <tendon>
        <spatial name="bicep" width="0.009" rgba=".4 .6 .4 1">
            <site site="site0"/>
            <geom geom="geom_shoulder" sidesite="x0"/>
            <site site="site1"/>
            <geom geom="geom_elbow" sidesite="x1"/>
            <site site="site2"/>
        </spatial>
    </tendon>

    <actuator>
        <muscle name="bicep" tendon="bicep" lengthrange="0 5" ctrlrange="0 1"/>
    </actuator>
</mujoco>